Workbook

Sheet devis
A1: Event Dream
B5: Event Dream
B6: 98 Rue Jean Jaurès
B7: 94800 Villejuif
B8: (33) 06 52 36 08 49
B11: Devis
B12: Envoyée le | C12: =TODAY() -> 45547
B14: Devis pour | F14: N° de devis
B15: Nom : | F15: =INDIRECT("'information général'!B4") -> 2912
B16: telephone :
B17: adresse : | F17: Date de location
F18: 45565
B23: Description | E23: Qté | F23: Prix unitaire | G23: Prix total
F24: =IF(B24="", "", IFERROR(VLOOKUP(B24, 'liste de matériel'!A:B, 2, FALSE), "")) | G24: =IF(E24*F24=0,"",E24*F24)
F25: =IF(B25="", "", IFERROR(VLOOKUP(B25, 'liste de matériel'!A:B, 2, FALSE), "")) | G25: =IF(E25*F25=0,"",E25*F25)
F26: =IF(B26="", "", IFERROR(VLOOKUP(B26, 'liste de matériel'!A:B, 2, FALSE), "")) | G26: =IF(E26*F26=0,"",E26*F26)
F27: =IF(B27="", "", IFERROR(VLOOKUP(B27, 'liste de matériel'!A:B, 2, FALSE), "")) | G27: =IF(E27*F27=0,"",E27*F27)
F28: =IF(B28="", "", IFERROR(VLOOKUP(B28, 'liste de matériel'!A:B, 2, FALSE), "")) | G28: =IF(E28*F28=0,"",E28*F28)
F29: =IF(B29="", "", IFERROR(VLOOKUP(B29, 'liste de matériel'!A:B, 2, FALSE), "")) | G29: =IF(E29*F29=0,"",E29*F29)
F30: =IF(B30="", "", IFERROR(VLOOKUP(B30, 'liste de matériel'!A:B, 2, FALSE), "")) | G30: =IF(E30*F30=0,"",E30*F30)
F31: =IF(B31="", "", IFERROR(VLOOKUP(B31, 'liste de matériel'!A:B, 2, FALSE), "")) | G31: =IF(E31*F31=0,"",E31*F31)
F32: =IF(B32="", "", IFERROR(VLOOKUP(B32, 'liste de matériel'!A:B, 2, FALSE), "")) | G32: =IF(E32*F32=0,"",E32*F32)
F33: =IF(B33="", "", IFERROR(VLOOKUP(B33, 'liste de matériel'!A:B, 2, FALSE), "")) | G33: =IF(E33*F33=0,"",E33*F33)
F34: =IF(B34="", "", IFERROR(VLOOKUP(B34, 'liste de matériel'!A:B, 2, FALSE), "")) | G34: =IF(E34*F34=0,"",E34*F34)
F35: =IF(B35="", "", IFERROR(VLOOKUP(B35, 'liste de matériel'!A:B, 2, FALSE), "")) | G35: =IF(E35*F35=0,"",E35*F35)
... F37: =IF(B37="", "", IFERROR(VLOOKUP(B37, 'liste de matériel'!A:B, 2, FALSE), "")) | G37: =IF(E37*F37=0,"",E37*F37)
F38: Sous-total H.T | G38: =SUM(G24:G37)-G39 -> 0
B39: Remarques : | F39: TVA | G39: =SUM(G24:G37)*0.2 -> 0
F40: =SUM(G38,G39) -> 0

Sheet information général
B3: Numéro de devis | C3: date | D3: nom prénom | E3: date de location | F3: retour de location | G3: adresse de livraison | H3: Caution | I3: Reste dû | J3: Acompte | K3: somme total
B4: =B5+1 -> 2912 | C4: =devis!C12 -> 45547 | E4: 45565 | F4: =E4+2 -> 45567 | G4: =devis!C17 | I4: =K4-J4 -> 0 | K4: =devis!F40 -> 0
B5: =B6+1 -> 2911 | C5: =devis!C10 | D5: TESTE 1 | G5: =devis!C17 | I5: =K5-J5 -> 0 | K5: =devis!F40 -> 0
B6: =B7+1 -> 2910 | C6: =devis!C11 | D6: TESTE 2 | E6: =devis!F19 | F6: =E6+2 -> 2 | G6: =devis!C17 | I6: =K6-J6 -> 0 | K6: =devis!F40 -> 0
B7: =B8+1 -> 2909 | C7: =devis!C12 -> 45547 | D7: TESTE 3 | E7: 45565 | F7: =E7+2 -> 45567 | G7: =devis!C17 | I7: =K7-J7 -> 0 | K7: =devis!F40 -> 0
B8: =B9+1 -> 2908 | C8: =devis!C12 -> 45547 | D8: HANANE
B9: 2907 | C9: 45497 | D9: nafea said | E9: 45591 | F9: 45593 | G9: 7 rue auguste renoir | H9: 400

Sheet contrat
Q3: Contrat de Location de Matériel Event Dreams
AO53: Rendre les meilleurs moments plus spéciaux
B59: Contrat de location
E64: Le présent contrat de location de matériel est établi et conclu le | AY64: =INDIRECT("'information général'!E4") -> 45565 | BH64: entre Eventdream et
E65: =INDIRECT("'information général'!D4") | AD65: ; collectivement dénommées" les “parties”.
E66: Le propriétaire loue le matériel suivant au locataire, qui doit adhérer aux termes et conditions du présent
E67: contrat :
N69: ↳ Les Parties conviennent de ce qui suit :
H72: 1- MATÉRIEL.
D73: Description du matériel | AO73: Quantité | AW73: Prix unitaire | BH73: Sous-total | BR73: Prix unité endommagé
D75: =devis!B24 | AO75: =devis!E24 | AW75: =devis!F24 | BH75: =devis!G24 | BR75: =devis!N12
D76: =devis!B25 | AO76: =devis!E25 | AW76: =devis!F25 | BH76: =devis!G25 | BR76: =devis!N13
D77: =devis!B26 | AO77: =devis!E26 | AW77: =devis!F26 | BH77: =devis!G26 | BR77: =devis!N14
D78: =devis!B27 | AO78: =devis!E27 | AW78: =devis!F27 | BH78: =devis!G27 | BR78: =devis!N15
D79: =devis!B28 | AO79: =devis!E28 | AW79: =devis!F28 | BH79: =devis!G28 | BR79: =devis!N16
D80: =devis!B29 | AO80: =devis!E29 | AW80: =devis!F29 | BH80: =devis!G29 | BR80: =devis!N17
D81: =devis!B30 | AO81: =devis!E30 | AW81: =devis!F30 | BH81: =devis!G30 | BR81: =devis!N19
D82: =devis!B31 | AO82: =devis!E31 | AW82: =devis!F31 | BH82: =devis!G31 | BR82: =devis!N21
D83: =devis!B32 | AO83: =devis!E32 | AW83: =devis!F32 | BH83: =devis!G32 | BR83: =devis!N22
D84: =devis!B33 | AO84: =devis!E33 | AW84: =devis!F33 | BH84: =devis!G33 | BR84: =devis!N23
D85: =devis!B34 | AO85: =devis!E34 | AW85: =devis!F34 | BH85: =devis!G34 | BR85: =devis!N24
D86: =devis!B35 | AO86: =devis!E35 | AW86: =devis!F35 | BH86: =devis!G35 | BR86: =devis!N26
D87: =devis!B36 | AO87: =devis!E36 | AW87: =devis!F36 | BH87: =devis!G36 | BR87: =devis!N27
D88: =devis!B37 | AO88: =devis!E37 | AW88: =devis!F37 | BH88: =devis!G37 | BR88: =devis!N28
D89: TOTAL | AO89: =devis!F40 -> 0 | BR89: =devis!N29
H94: 2- DURÉE DE LA LOCATION.
E95: La période de location commencera le | AG95: =INDIRECT("'information général'!E4") -> 45565 | AQ95: et se terminera le | BD95: =INDIRECT("'information général'!F4") -> 45567
H98: 3- MONTANT DE LA LOCATION.
E99: Le locataire s'engage à payer le montant de | AK99: =AO89 -> 0 | AS99: au propriétaire en tant que loyer pour le matériel.
E100: En déduction de l’acompte déjà payé d'une valeur de | AR100: =INDIRECT("'information général'!J4") | AW100: Reste dû : | BF100: =INDIRECT("'information général'!I4") -> 0
H103: 4- FRAIS SUPPLÉMENTAIRES.
E104: Des frais supplémentaires seront ajoutés dans le cas où le matériel est endommagé ,
E105: manque des pièces, ou est retourné plus tard que la durée de location.
B113: Contrat de location
H123: 5- UTILISATION DU MATÉRIEL
E124: Le matériel doit être utilisé de manière prudente et appropriée. Son utilisation doit être
E125: conforme à toutes les lois et réglementations relatives à la possession, l'utilisation
E126: ou l'entretien du matériel.
H130: 6- DÉPÔT DE GARANTIE.
E131: En plus des frais de location, le locataire devra verser un dépôt de garantie de | BI131: =INDIRECT("'information général'!H4")
...

Sheet facture

Sheet liste de matériel
A1: matériel | B1: prix de location | C1: prix d'achat
A2: table ronde | B2: 11 | C2: 70
A3: table rectangulaire | B3: 11 | C3: 50
A4: fourchette | B4: 0.3 | C4: 0.5
A5: petite cuillères | B5: 0.75 | C5: 0.5
A6: grande cuillére | B6: 0.75
A7: petite ascette V1 | B7: 0.75
A8: grande ascette V1 | B8: 0.75
A9: petite asciette préstige | B9: 1
A10: grande asciette préstige | B10: 1
A11: chaise nappoléon | B11: 3
A12: chaise pliante noir | B12: 1.75
A13: hausse de chaise | B13: 1
A14: nappe rond blanche | B14: 8
A15: nappe réctangulaire | B15: 8
A16: livraison au pied de camion

Sheet commandes
A5: Cofirmé ou pas ? | B5: N° de devis | C5: Date de sortie | D5: Date de retour | E5: Matériel loué | F5: total mensuel | G5: livraison | H5: montant total | I5: Acompte payé | J5: reste à payer | K5: adresse de livraison | L5: Moyen de contact | M5: Nom | N5: Mtt du chèque | O5: Heure du retrait
A6: documents | B6: nadia | C6: 44755 | D6: 44757 | E6: 3 tables 30 chaises | H6: 68 | I6: 0 | J6: 68
A7: FATAH | B7: fatah | C7: 44820 | D7: 44822 | E7: 2 table 2 nappe | H7: 32 | I7: 0 | J7: 32
A8: BAYA | B8: baya | C8: 44820 | D8: 44822 | E8: 100 kit vaisselle 10 tables 10 nappes mange debeou nappe | H8: 240 | I8: 0 | J8: 240
B9: RETIBALLAH | C9: 44841 | D9: 44843 | E9: 2 table 2 nappes | F9: =SUM(H9:H14) -> 584 | G9: 36 | H9: 68 | I9: 0 | J9: 68
B10: AWA | C10: 44847 | D10: 44849 | E10: 140 verres | F10: =SUM(H15:H18) -> 279 | H10: 84 | I10: 0 | J10: 84
B11: stephanie | C11: 44848 | D11: 44850 | E11: 12 table | H11: 96 | I11: 0 | J11: 96
C12: 44848 | D12: 44850 | E12: 30 cHAISE | H12: 30 | I12: 0 | J12: 30
B13: julie | C13: 44856 | D13: 44859 | E13: 136 kit vaisselle /S | H13: 170 | I13: 60 | J13: 110
B14: norah | C14: 44856 | D14: 44859 | E14: 7 tables ronde | G14: 80 | H14: 136 | I14: 34.61 | J14: 0
B15: AYMEN | C15: 44863 | D15: 44866 | E15: 25 kits | H15: 25 | I15: 0 | J15: 25
C16: 44876 | D16: 44878 | E16: 120 KIT/S | H16: 150 | I16: 50 | J16: 100
B17: PINDA | C17: 44876 | D17: 44878 | E17: 3 TABLES | H17: 24 | I17: 0 | J17: 24
B18: NAIMA | C18: 44892 | D18: 44894 | E18: 80 KITS | H18: 80 | I18: 0 | J18: 80
A19: LEILA | B19: LEILA | C19: 44897 | D19: 44899 | E19: 5 tables 5 NAPPES RONDE 4 NAPPE RECT LIV | F19: =SUM(H19:H20) -> 215 | G19: 38 | H19: 150 | I19: 50
A20: jsp | B20: HOUSSE | C20: 44905 | D20: 44905 | E20: 40 housse | G20: 33 | H20: 65 | I20: 0 | J20: 65
B21: Amina sidhoum | C21: 44944 | D21: 44946 | E21: 80 kits | F21: =SUM(H21:Z24) -> 640 | H21: 80 | I21: 0 | J21: 80
B22: CHAISE | C22: 44953 | D22: 44946 | E22: 2tables rectan 20 kits 20 housse | G22: 28 | H22: 80 | I22: 0 | J22: 80
A23: jsp | B23: TABLE | C23: 44953 | D23: 44955 | E23: 8 Tables | G23: 16 | H23: 80 | I23: 0 | J23: 80
A24: sidhoum | C24: 44953 | D24: 44955 | E24: 40 chaises | G24: 40 | H24: 80 | I24: 25 | J24: 55
A25: JSP | C25: 44960 | D25: 44962 | E25: 35 chaises 1 table rect | F25: =SUM(H25:H34) -> 636.96 | G25: 29.98 | H25: 74.98 | I25: 0 | J25: 75
A26: JSP | B26: CHAISE | C26: 44961 | D26: 44963 | E26: 35 CHAISE LIV 1 TABLE RECT | G26: =65-35-8 -> 22 | H26: 64.98 | I26: 0 | J26: 65
A27: benzid sonia | C27: 44968 | D27: 44970 | E27: 80 kits | H27: 80 | I27: 25 | J27: 55
A28: jsp | C28: 44969 | D28: 44971 | E28: 12 chaises | H28: 0
A29: bensalem | C29: 44974 | D29: 44975 | E29: 4 tables et 4 nappes rondes | H29: 72 | I29: 27 | J29: 45 | K29: NON | L29: WTHSAP (4tables et 4 nappes) | M29: Myriam Bensalem | N29: 200 | O29: 14H30
A30: JSPg | C30: 44974 | D30: 44976 | E30: 30 chaises | G30: 39.99 | H30: 69.98€ | I30: 24.98€ | J30: 45 | K30: Paris 12 | L30: Leboncoin(dembele) | M30: Bintou Dembele | N30: 100
A31: JSP | C31: 44974 | D31: 44977 | E31: 3O chaises | G31: 39.99 | H31: 69.98€ | I31: 24.98€ | J31: 45 | K31: Massy Palaiseau | L31: Assos 30 chaises (wtsp) | M31: Baptiste Copin | N31: 100
A32: JSP | C32: 44975 | D32: 44975 | E32: 8 tables | G32: 30 | H32: 140 | I32: 0 | J32: 140 | K32: Champigny | L32: Urgent | N32: 400
A33: BOUDFOUSS | C33: 44978 | D33: 44979 | E33: 25 Chaises | H33: 25 | I33: 0 | J33: 25 | K33: NON | L33: Naissance Omra | N33: 100 | O33: 12h00
A34: halimata | B34: via msg 15 FEV | C34: 44981 | D34: 44982 | E34: 200 kits ( assiette cuilliere verre ) | H34: 180 | I34: 180 | J34: 0 | L34: 150 kits sevran
A35: contrat Ingrid.pdf | B35: 23_02_2023_IngridK | C35: 44988 | D35: 44989 | E35: 100 Kit propre | F35: =SUM(H35:H40) -> 283.8 | H35: 100 | I35: 30 | J35: 70 | K35: NON | L35: INGRIDK(leboncoin) | N35: 250
A36: JSP | B36: Devis_24_02_2023 | C36: 44988 | D36: 44989 | E36: 35 Chaises | G36: 25 | H36: 85 | I36: 25 | J36: 60 | K36: Rosny-sous-Bois | L36: Ams 35 Chaises | M36: Adjinaya Fatoumata | N36: 200 | O36: 16h30 et retrait à 18h00 | P36: 5 Rue de lisbonne 93 110 Rosny-sous-bois
B37: Devis_06_03_2023 | C37: 44993 | D37: 44998 | E37: 70 chaises et 50 housses | G37: 39.98 | H37: 259.98€ | I37: 84.98€ | J37: 175 | K37: Paris 12 | L37: Mme Connet | M37: Fatoumata Kone | N37: 500
A38: jsp | C38: 45002 | D38: 45003 | E38: 50 chaises | H38: 50 | I38: 15 | J38: 35 | K38: NON | L38: Leboncoin(Z.ROD) | M38: Rodolphe Zadi | N38: 100
A39: pearl caffa | B39: Devis_11_03_2023 | C39: 45002 | D39: 45004 | E39: 20 Chaises +2 housse +livraison à Paris 13 | G39: 38.38 | H39: 59.98€ | I39: 0 | J39: 59.98 | K39: Paris 13 | L39: Leboncoin(Pearlychouw)
A40: JSP | C40: 45003 | D40: 45005 | E40: 11 chaises 11 housse 1 nappe table 11 kit vaisselle | H40: 48.8 | I40: 18.8 | J40: 30
A41: JSP | C41: 45024 | D41: 45026 | E41: 30 CHAISE | F41: =SUM(H41:H45) -> 473 | H41: 30 | I41: 0 | J41: 30
A42: jsp | C42: 45036 | D42: 45038 | E42: 20 chaises | H42: 20 | I42: 0 | J42: 20
A43: contrat de location ismahane.pdf | B43: 26_02_2023_Sarah | C43: 45037 | D43: 45038 | E43: 6 tables rondes chaises housse nappes centre | G43: 39 | H43: 323 | I43: 113 | J43: 210 | K43: Villejuif | L43: Leboncoin (Sarah) | M43: Ismahane el Mir | N43: 450 | P43: 5 Allée Sonia delaunay, villejuif
A44: contrat leslie.pdf | B44: Pas de devis | C44: 45044 | D44: 45046 | E44: 30 Chaise | H44: 30 | I44: 30 | J44: 0 | K44: NON | L44: Leboncoin (Leslie) | M44: Leslie Noundou | N44: 150 | O44: Samedi à 11H00
...
